Workbook

Sheet Data
A1: Project Name | B1: Supplier | C1: Product | D1: Quantity | E1: Unit Price | F1: Total | G1: Start Date | H1: Project Duration (Weeks) | I1: Deadline | J1: Payment Status | K1: Status | L1: DateOK | M1: MatchAll | N1: MatchExclProduct | O1: MatchExclSupplier | P1: MatchExclStatus | Q1: MatchExclProject | R1: MatchExclPayment | S1: RowIdx | T1: ProjectList | U1: SupplierList | V1: ProductList
A2: FRA | B2: Wireless dynamics | C2: TC 56 handheld | D2: 2 | E2: 2 | F2: =IF(E2="","",D2*E2) -> 4 | G2: 46144 | H2: 1 | I2: =IF(OR(G2="",H2=""),"",G2+H2*7) -> 46151 | J2: Not Paid | K2: Completed | L2: =IF(A2="","",IF(OR(G2="",AND(G2>=Dashboard!$C$18,G2<=Dashboard!$C$19)),1,0)) -> 1 | M2: =IF(AND(L2=1,OR(Dashboard!$C$13="All",A2=Dashboard!$C$13),OR(Dashboard!$C$14="All",B2=Dashboard!$C$14),OR(Dashboard!$C$15="All",C2=Dashboard!$C$15),OR(Dashboard!$C$16="All",K2=Dashboard!$C$16),OR(Dashboard!$C$17="All",J2=Dashboard!$C$17)),1,0) -> 1 | N2: =IF(AND(L2=1,OR(Dashboard!$C$13="All",A2=Dashboard!$C$13),OR(Dashboard!$C$14="All",B2=Dashboard!$C$14),OR(Dashboard!$C$16="All",K2=Dashboard!$C$16),OR(Dashboard!$C$17="All",J2=Dashboard!$C$17)),1,0) -> 1 | O2: =IF(AND(L2=1,OR(Dashboard!$C$13="All",A2=Dashboard!$C$13),OR(Dashboard!$C$15="All",C2=Dashboard!$C$15),OR(Dashboard!$C$16="All",K2=Dashboard!$C$16),OR(Dashboard!$C$17="All",J2=Dashboard!$C$17)),1,0) -> 1 | P2: =IF(AND(L2=1,OR(Dashboard!$C$13="All",A2=Dashboard!$C$13),OR(Dashboard!$C$14="All",B2=Dashboard!$C$14),OR(Dashboard!$C$15="All",C2=Dashboard!$C$15),OR(Dashboard!$C$17="All",J2=Dashboard!$C$17)),1,0) -> 1 | Q2: =IF(AND(L2=1,OR(Dashboard!$C$14="All",B2=Dashboard!$C$14),OR(Dashboard!$C$15="All",C2=Dashboard!$C$15),OR(Dashboard!$C$16="All",K2=Dashboard!$C$16),OR(Dashboard!$C$17="All",J2=Dashboard!$C$17)),1,0) -> 1 | R2: =IF(AND(L2=1,OR(Dashboard!$C$13="All",A2=Dashboard!$C$13),OR(Dashboard!$C$14="All",B2=Dashboard!$C$14),OR(Dashboard!$C$15="All",C2=Dashboard!$C$15),OR(Dashboard!$C$16="All",K2=Dashboard!$C$16)),1,0) -> 1 | S2: =IF(M2=1,ROW()-1,"") -> 1 | T2: All | U2: All | V2: All
A3: FRA | B3: Fusion | C3: [5118.001.01] ID MAX.U500i-EU Compact UHF Access Control Re | D3: 2 | E3: 5 | F3: =IF(E3="","",D3*E3) -> 10 | G3: 46145 | H3: 2 | I3: =IF(OR(G3="",H3=""),"",G3+H3*7) -> 46159 | J3: Advance Payment | K3: Pending | L3: =IF(A3="","",IF(OR(G3="",AND(G3>=Dashboard!$C$18,G3<=Dashboard!$C$19)),1,0)) -> 1 | M3: =IF(AND(L3=1,OR(Dashboard!$C$13="All",A3=Dashboard!$C$13),OR(Dashboard!$C$14="All",B3=Dashboard!$C$14),OR(Dashboard!$C$15="All",C3=Dashboard!$C$15),OR(Dashboard!$C$16="All",K3=Dashboard!$C$16),OR(Dashboard!$C$17="All",J3=Dashboard!$C$17)),1,0) -> 1 | N3: =IF(AND(L3=1,OR(Dashboard!$C$13="All",A3=Dashboard!$C$13),OR(Dashboard!$C$14="All",B3=Dashboard!$C$14),OR(Dashboard!$C$16="All",K3=Dashboard!$C$16),OR(Dashboard!$C$17="All",J3=Dashboard!$C$17)),1,0) -> 1 | O3: =IF(AND(L3=1,OR(Dashboard!$C$13="All",A3=Dashboard!$C$13),OR(Dashboard!$C$15="All",C3=Dashboard!$C$15),OR(Dashboard!$C$16="All",K3=Dashboard!$C$16),OR(Dashboard!$C$17="All",J3=Dashboard!$C$17)),1,0) -> 1 | P3: =IF(AND(L3=1,OR(Dashboard!$C$13="All",A3=Dashboard!$C$13),OR(Dashboard!$C$14="All",B3=Dashboard!$C$14),OR(Dashboard!$C$15="All",C3=Dashboard!$C$15),OR(Dashboard!$C$17="All",J3=Dashboard!$C$17)),1,0) -> 1 | Q3: =IF(AND(L3=1,OR(Dashboard!$C$14="All",B3=Dashboard!$C$14),OR(Dashboard!$C$15="All",C3=Dashboard!$C$15),OR(Dashboard!$C$16="All",K3=Dashboard!$C$16),OR(Dashboard!$C$17="All",J3=Dashboard!$C$17)),1,0) -> 1 | R3: =IF(AND(L3=1,OR(Dashboard!$C$13="All",A3=Dashboard!$C$13),OR(Dashboard!$C$14="All",B3=Dashboard!$C$14),OR(Dashboard!$C$15="All",C3=Dashboard!$C$15),OR(Dashboard!$C$16="All",K3=Dashboard!$C$16)),1,0) -> 1 | S3: =IF(M3=1,ROW()-1,"") -> 2 | T3: FRA | U3: ATC | V3: MET QR Code Scanner
A4: FRA | B4: Metalcraft | C4: EU Universal tags | D4: 1000 | E4: 6 | F4: =IF(E4="","",D4*E4) -> 6000 | G4: 46146 | H4: 4 | I4: =IF(OR(G4="",H4=""),"",G4+H4*7) -> 46174 | J4: Fully Paid | K4: In Progress | L4: =IF(A4="","",IF(OR(G4="",AND(G4>=Dashboard!$C$18,G4<=Dashboard!$C$19)),1,0)) -> 1 | M4: =IF(AND(L4=1,OR(Dashboard!$C$13="All",A4=Dashboard!$C$13),OR(Dashboard!$C$14="All",B4=Dashboard!$C$14),OR(Dashboard!$C$15="All",C4=Dashboard!$C$15),OR(Dashboard!$C$16="All",K4=Dashboard!$C$16),OR(Dashboard!$C$17="All",J4=Dashboard!$C$17)),1,0) -> 1 | N4: =IF(AND(L4=1,OR(Dashboard!$C$13="All",A4=Dashboard!$C$13),OR(Dashboard!$C$14="All",B4=Dashboard!$C$14),OR(Dashboard!$C$16="All",K4=Dashboard!$C$16),OR(Dashboard!$C$17="All",J4=Dashboard!$C$17)),1,0) -> 1 | O4: =IF(AND(L4=1,OR(Dashboard!$C$13="All",A4=Dashboard!$C$13),OR(Dashboard!$C$15="All",C4=Dashboard!$C$15),OR(Dashboard!$C$16="All",K4=Dashboard!$C$16),OR(Dashboard!$C$17="All",J4=Dashboard!$C$17)),1,0) -> 1 | P4: =IF(AND(L4=1,OR(Dashboard!$C$13="All",A4=Dashboard!$C$13),OR(Dashboard!$C$14="All",B4=Dashboard!$C$14),OR(Dashboard!$C$15="All",C4=Dashboard!$C$15),OR(Dashboard!$C$17="All",J4=Dashboard!$C$17)),1,0) -> 1 | Q4: =IF(AND(L4=1,OR(Dashboard!$C$14="All",B4=Dashboard!$C$14),OR(Dashboard!$C$15="All",C4=Dashboard!$C$15),OR(Dashboard!$C$16="All",K4=Dashboard!$C$16),OR(Dashboard!$C$17="All",J4=Dashboard!$C$17)),1,0) -> 1 | R4: =IF(AND(L4=1,OR(Dashboard!$C$13="All",A4=Dashboard!$C$13),OR(Dashboard!$C$14="All",B4=Dashboard!$C$14),OR(Dashboard!$C$15="All",C4=Dashboard!$C$15),OR(Dashboard!$C$16="All",K4=Dashboard!$C$16)),1,0) -> 1 | S4: =IF(M4=1,ROW()-1,"") -> 3 | T4: El Kasr | U4: ATID | V4: (SBH01) Barrier Beam Connection piece Flange
A5: FRA | B5: Dipole | C5: Dogbone | D5: 3500 | E5: 7 | F5: =IF(E5="","",D5*E5) -> 24500 | G5: 46147 | H5: 6 | I5: =IF(OR(G5="",H5=""),"",G5+H5*7) -> 46189 | J5: Advance Payment | K5: Completed | L5: =IF(A5="","",IF(OR(G5="",AND(G5>=Dashboard!$C$18,G5<=Dashboard!$C$19)),1,0)) -> 1 | M5: =IF(AND(L5=1,OR(Dashboard!$C$13="All",A5=Dashboard!$C$13),OR(Dashboard!$C$14="All",B5=Dashboard!$C$14),OR(Dashboard!$C$15="All",C5=Dashboard!$C$15),OR(Dashboard!$C$16="All",K5=Dashboard!$C$16),OR(Dashboard!$C$17="All",J5=Dashboard!$C$17)),1,0) -> 1 | N5: =IF(AND(L5=1,OR(Dashboard!$C$13="All",A5=Dashboard!$C$13),OR(Dashboard!$C$14="All",B5=Dashboard!$C$14),OR(Dashboard!$C$16="All",K5=Dashboard!$C$16),OR(Dashboard!$C$17="All",J5=Dashboard!$C$17)),1,0) -> 1 | O5: =IF(AND(L5=1,OR(Dashboard!$C$13="All",A5=Dashboard!$C$13),OR(Dashboard!$C$15="All",C5=Dashboard!$C$15),OR(Dashboard!$C$16="All",K5=Dashboard!$C$16),OR(Dashboard!$C$17="All",J5=Dashboard!$C$17)),1,0) -> 1 | P5: =IF(AND(L5=1,OR(Dashboard!$C$13="All",A5=Dashboard!$C$13),OR(Dashboard!$C$14="All",B5=Dashboard!$C$14),OR(Dashboard!$C$15="All",C5=Dashboard!$C$15),OR(Dashboard!$C$17="All",J5=Dashboard!$C$17)),1,0) -> 1 | Q5: =IF(AND(L5=1,OR(Dashboard!$C$14="All",B5=Dashboard!$C$14),OR(Dashboard!$C$15="All",C5=Dashboard!$C$15),OR(Dashboard!$C$16="All",K5=Dashboard!$C$16),OR(Dashboard!$C$17="All",J5=Dashboard!$C$17)),1,0) -> 1 | R5: =IF(AND(L5=1,OR(Dashboard!$C$13="All",A5=Dashboard!$C$13),OR(Dashboard!$C$14="All",B5=Dashboard!$C$14),OR(Dashboard!$C$15="All",C5=Dashboard!$C$15),OR(Dashboard!$C$16="All",K5=Dashboard!$C$16)),1,0) -> 1 | S5: =IF(M5=1,ROW()-1,"") -> 4 | T5: Harvest | U5: Avery Dennison/Dipole | V5: 15 coaxial cable
A6: FRA | B6: Jarltech | C6: FX9600 Reader | D6: 18 | E6: 8 | F6: =IF(E6="","",D6*E6) -> 144 | G6: 46148 | H6: 8 | I6: =IF(OR(G6="",H6=""),"",G6+H6*7) -> 46204 | J6: Fully Paid | K6: Delayed | L6: =IF(A6="","",IF(OR(G6="",AND(G6>=Dashboard!$C$18,G6<=Dashboard!$C$19)),1,0)) -> 1 | M6: =IF(AND(L6=1,OR(Dashboard!$C$13="All",A6=Dashboard!$C$13),OR(Dashboard!$C$14="All",B6=Dashboard!$C$14),OR(Dashboard!$C$15="All",C6=Dashboard!$C$15),OR(Dashboard!$C$16="All",K6=Dashboard!$C$16),OR(Dashboard!$C$17="All",J6=Dashboard!$C$17)),1,0) -> 1 | N6: =IF(AND(L6=1,OR(Dashboard!$C$13="All",A6=Dashboard!$C$13),OR(Dashboard!$C$14="All",B6=Dashboard!$C$14),OR(Dashboard!$C$16="All",K6=Dashboard!$C$16),OR(Dashboard!$C$17="All",J6=Dashboard!$C$17)),1,0) -> 1 | O6: =IF(AND(L6=1,OR(Dashboard!$C$13="All",A6=Dashboard!$C$13),OR(Dashboard!$C$15="All",C6=Dashboard!$C$15),OR(Dashboard!$C$16="All",K6=Dashboard!$C$16),OR(Dashboard!$C$17="All",J6=Dashboard!$C$17)),1,0) -> 1 | P6: =IF(AND(L6=1,OR(Dashboard!$C$13="All",A6=Dashboard!$C$13),OR(Dashboard!$C$14="All",B6=Dashboard!$C$14),OR(Dashboard!$C$15="All",C6=Dashboard!$C$15),OR(Dashboard!$C$17="All",J6=Dashboard!$C$17)),1,0) -> 1 | Q6: =IF(AND(L6=1,OR(Dashboard!$C$14="All",B6=Dashboard!$C$14),OR(Dashboard!$C$15="All",C6=Dashboard!$C$15),OR(Dashboard!$C$16="All",K6=Dashboard!$C$16),OR(Dashboard!$C$17="All",J6=Dashboard!$C$17)),1,0) -> 1 | R6: =IF(AND(L6=1,OR(Dashboard!$C$13="All",A6=Dashboard!$C$13),OR(Dashboard!$C$14="All",B6=Dashboard!$C$14),OR(Dashboard!$C$15="All",C6=Dashboard!$C$15),OR(Dashboard!$C$16="All",K6=Dashboard!$C$16)),1,0) -> 1 | S6: =IF(M6=1,ROW()-1,"") -> 5 | T6: Lavista Patios | U6: Confidex | V6: 70 coaxial cable
A7: FRA | B7: Jarltech | C7: AN480 Antenna | D7: 37 | E7: 2 | F7: =IF(E7="","",D7*E7) -> 74 | G7: 46149 | H7: 9 | I7: =IF(OR(G7="",H7=""),"",G7+H7*7) -> 46212 | J7: Not Paid | K7: Pending | L7: =IF(A7="","",IF(OR(G7="",AND(G7>=Dashboard!$C$18,G7<=Dashboard!$C$19)),1,0)) -> 1 | M7: =IF(AND(L7=1,OR(Dashboard!$C$13="All",A7=Dashboard!$C$13),OR(Dashboard!$C$14="All",B7=Dashboard!$C$14),OR(Dashboard!$C$15="All",C7=Dashboard!$C$15),OR(Dashboard!$C$16="All",K7=Dashboard!$C$16),OR(Dashboard!$C$17="All",J7=Dashboard!$C$17)),1,0) -> 1 | N7: =IF(AND(L7=1,OR(Dashboard!$C$13="All",A7=Dashboard!$C$13),OR(Dashboard!$C$14="All",B7=Dashboard!$C$14),OR(Dashboard!$C$16="All",K7=Dashboard!$C$16),OR(Dashboard!$C$17="All",J7=Dashboard!$C$17)),1,0) -> 1 | O7: =IF(AND(L7=1,OR(Dashboard!$C$13="All",A7=Dashboard!$C$13),OR(Dashboard!$C$15="All",C7=Dashboard!$C$15),OR(Dashboard!$C$16="All",K7=Dashboard!$C$16),OR(Dashboard!$C$17="All",J7=Dashboard!$C$17)),1,0) -> 1 | P7: =IF(AND(L7=1,OR(Dashboard!$C$13="All",A7=Dashboard!$C$13),OR(Dashboard!$C$14="All",B7=Dashboard!$C$14),OR(Dashboard!$C$15="All",C7=Dashboard!$C$15),OR(Dashboard!$C$17="All",J7=Dashboard!$C$17)),1,0) -> 1 | Q7: =IF(AND(L7=1,OR(Dashboard!$C$14="All",B7=Dashboard!$C$14),OR(Dashboard!$C$15="All",C7=Dashboard!$C$15),OR(Dashboard!$C$16="All",K7=Dashboard!$C$16),OR(Dashboard!$C$17="All",J7=Dashboard!$C$17)),1,0) -> 1 | R7: =IF(AND(L7=1,OR(Dashboard!$C$13="All",A7=Dashboard!$C$13),OR(Dashboard!$C$14="All",B7=Dashboard!$C$14),OR(Dashboard!$C$15="All",C7=Dashboard!$C$15),OR(Dashboard!$C$16="All",K7=Dashboard!$C$16)),1,0) -> 1 | S7: =IF(M7=1,ROW()-1,"") -> 6 | T7: Layan | U7: Cube | V7: [14229] Paper tags (Dogbone) Blank
A8: FRA | B8: Local | C8: Protection cap | D8: 18 | E8: 15 | F8: =IF(E8="","",D8*E8) -> 270 | G8: 46150 | H8: 4 | I8: =IF(OR(G8="",H8=""),"",G8+H8*7) -> 46178 | J8: Advance Payment | K8: Completed | L8: =IF(A8="","",IF(OR(G8="",AND(G8>=Dashboard!$C$18,G8<=Dashboard!$C$19)),1,0)) -> 1 | M8: =IF(AND(L8=1,OR(Dashboard!$C$13="All",A8=Dashboard!$C$13),OR(Dashboard!$C$14="All",B8=Dashboard!$C$14),OR(Dashboard!$C$15="All",C8=Dashboard!$C$15),OR(Dashboard!$C$16="All",K8=Dashboard!$C$16),OR(Dashboard!$C$17="All",J8=Dashboard!$C$17)),1,0) -> 1 | N8: =IF(AND(L8=1,OR(Dashboard!$C$13="All",A8=Dashboard!$C$13),OR(Dashboard!$C$14="All",B8=Dashboard!$C$14),OR(Dashboard!$C$16="All",K8=Dashboard!$C$16),OR(Dashboard!$C$17="All",J8=Dashboard!$C$17)),1,0) -> 1 | O8: =IF(AND(L8=1,OR(Dashboard!$C$13="All",A8=Dashboard!$C$13),OR(Dashboard!$C$15="All",C8=Dashboard!$C$15),OR(Dashboard!$C$16="All",K8=Dashboard!$C$16),OR(Dashboard!$C$17="All",J8=Dashboard!$C$17)),1,0) -> 1 | P8: =IF(AND(L8=1,OR(Dashboard!$C$13="All",A8=Dashboard!$C$13),OR(Dashboard!$C$14="All",B8=Dashboard!$C$14),OR(Dashboard!$C$15="All",C8=Dashboard!$C$15),OR(Dashboard!$C$17="All",J8=Dashboard!$C$17)),1,0) -> 1 | Q8: =IF(AND(L8=1,OR(Dashboard!$C$14="All",B8=Dashboard!$C$14),OR(Dashboard!$C$15="All",C8=Dashboard!$C$15),OR(Dashboard!$C$16="All",K8=Dashboard!$C$16),OR(Dashboard!$C$17="All",J8=Dashboard!$C$17)),1,0) -> 1 | R8: =IF(AND(L8=1,OR(Dashboard!$C$13="All",A8=Dashboard!$C$13),OR(Dashboard!$C$14="All",B8=Dashboard!$C$14),OR(Dashboard!$C$15="All",C8=Dashboard!$C$15),OR(Dashboard!$C$16="All",K8=Dashboard!$C$16)),1,0) -> 1 | S8: =IF(M8=1,ROW()-1,"") -> 7 | T8: Majid El futtaim | U8: Dipole | V8: [14229] Paper tags (Dogbone) Blank
A9: FRA | B9: Local | C9: Antenna Stand | D9: 37 | E9: 45 | F9: =IF(E9="","",D9*E9) -> 1665 | G9: 46151 | H9: 3 | I9: =IF(OR(G9="",H9=""),"",G9+H9*7) -> 46172 | J9: Fully Paid | K9: Pending | L9: =IF(A9="","",IF(OR(G9="",AND(G9>=Dashboard!$C$18,G9<=Dashboard!$C$19)),1,0)) -> 1 | M9: =IF(AND(L9=1,OR(Dashboard!$C$13="All",A9=Dashboard!$C$13),OR(Dashboard!$C$14="All",B9=Dashboard!$C$14),OR(Dashboard!$C$15="All",C9=Dashboard!$C$15),OR(Dashboard!$C$16="All",K9=Dashboard!$C$16),OR(Dashboard!$C$17="All",J9=Dashboard!$C$17)),1,0) -> 1 | N9: =IF(AND(L9=1,OR(Dashboard!$C$13="All",A9=Dashboard!$C$13),OR(Dashboard!$C$14="All",B9=Dashboard!$C$14),OR(Dashboard!$C$16="All",K9=Dashboard!$C$16),OR(Dashboard!$C$17="All",J9=Dashboard!$C$17)),1,0) -> 1 | O9: =IF(AND(L9=1,OR(Dashboard!$C$13="All",A9=Dashboard!$C$13),OR(Dashboard!$C$15="All",C9=Dashboard!$C$15),OR(Dashboard!$C$16="All",K9=Dashboard!$C$16),OR(Dashboard!$C$17="All",J9=Dashboard!$C$17)),1,0) -> 1 | P9: =IF(AND(L9=1,OR(Dashboard!$C$13="All",A9=Dashboard!$C$13),OR(Dashboard!$C$14="All",B9=Dashboard!$C$14),OR(Dashboard!$C$15="All",C9=Dashboard!$C$15),OR(Dashboard!$C$17="All",J9=Dashboard!$C$17)),1,0) -> 1 | Q9: =IF(AND(L9=1,OR(Dashboard!$C$14="All",B9=Dashboard!$C$14),OR(Dashboard!$C$15="All",C9=Dashboard!$C$15),OR(Dashboard!$C$16="All",K9=Dashboard!$C$16),OR(Dashboard!$C$17="All",J9=Dashboard!$C$17)),1,0) -> 1 | R9: =IF(AND(L9=1,OR(Dashboard!$C$13="All",A9=Dashboard!$C$13),OR(Dashboard!$C$14="All",B9=Dashboard!$C$14),OR(Dashboard!$C$15="All",C9=Dashboard!$C$15),OR(Dashboard!$C$16="All",K9=Dashboard!$C$16)),1,0) -> 1 | S9: =IF(M9=1,ROW()-1,"") -> 8 | T9: مخازن وزارة الصحة | U9: El Nekheely | V9: [3199.000.00] ID ISC.ANT.U270/270-EU Antenna UHF
A10: El Kasr | B10: Feig | C10: Jewelry tags | D10: 40000 | E10: 24 | F10: =IF(E10="","",D10*E10) -> 960000 | G10: 46152 | H10: 1 | I10: =IF(OR(G10="",H10=""),"",G10+H10*7) -> 46159 | J10: Advance Payment | K10: In Progress | L10: =IF(A10="","",IF(OR(G10="",AND(G10>=Dashboard!$C$18,G10<=Dashboard!$C$19)),1,0)) -> 1 | M10: =IF(AND(L10=1,OR(Dashboard!$C$13="All",A10=Dashboard!$C$13),OR(Dashboard!$C$14="All",B10=Dashboard!$C$14),OR(Dashboard!$C$15="All",C10=Dashboard!$C$15),OR(Dashboard!$C$16="All",K10=Dashboard!$C$16),OR(Dashboard!$C$17="All",J10=Dashboard!$C$17)),1,0) -> 1 | N10: =IF(AND(L10=1,OR(Dashboard!$C$13="All",A10=Dashboard!$C$13),OR(Dashboard!$C$14="All",B10=Dashboard!$C$14),OR(Dashboard!$C$16="All",K10=Dashboard!$C$16),OR(Dashboard!$C$17="All",J10=Dashboard!$C$17)),1,0) -> 1 | O10: =IF(AND(L10=1,OR(Dashboard!$C$13="All",A10=Dashboard!$C$13),OR(Dashboard!$C$15="All",C10=Dashboard!$C$15),OR(Dashboard!$C$16="All",K10=Dashboard!$C$16),OR(Dashboard!$C$17="All",J10=Dashboard!$C$17)),1,0) -> 1 | P10: =IF(AND(L10=1,OR(Dashboard!$C$13="All",A10=Dashboard!$C$13),OR(Dashboard!$C$14="All",B10=Dashboard!$C$14),OR(Dashboard!$C$15="All",C10=Dashboard!$C$15),OR(Dashboard!$C$17="All",J10=Dashboard!$C$17)),1,0) -> 1 | Q10: =IF(AND(L10=1,OR(Dashboard!$C$14="All",B10=Dashboard!$C$14),OR(Dashboard!$C$15="All",C10=Dashboard!$C$15),OR(Dashboard!$C$16="All",K10=Dashboard!$C$16),OR(Dashboard!$C$17="All",J10=Dashboard!$C$17)),1,0) -> 1 | R10: =IF(AND(L10=1,OR(Dashboard!$C$13="All",A10=Dashboard!$C$13),OR(Dashboard!$C$14="All",B10=Dashboard!$C$14),OR(Dashboard!$C$15="All",C10=Dashboard!$C$15),OR(Dashboard!$C$16="All",K10=Dashboard!$C$16)),1,0) -> 1 | S10: =IF(M10=1,ROW()-1,"") -> 9 | T10: Telal Elsahel | U10: FAAC | V10: [3908425] SkinPack 615 Barrier
A11: El Kasr | B11: Dipole | C11: Printer CT4LX | D11: 5 | E11: 25 | F11: =IF(E11="","",D11*E11) -> 125 | G11: 46153 | H11: 2 | I11: =IF(OR(G11="",H11=""),"",G11+H11*7) -> 46167 | J11: Fully Paid | K11: Completed | L11: =IF(A11="","",IF(OR(G11="",AND(G11>=Dashboard!$C$18,G11<=Dashboard!$C$19)),1,0)) -> 1 | M11: =IF(AND(L11=1,OR(Dashboard!$C$13="All",A11=Dashboard!$C$13),OR(Dashboard!$C$14="All",B11=Dashboard!$C$14),OR(Dashboard!$C$15="All",C11=Dashboard!$C$15),OR(Dashboard!$C$16="All",K11=Dashboard!$C$16),OR(Dashboard!$C$17="All",J11=Dashboard!$C$17)),1,0) -> 1 | N11: =IF(AND(L11=1,OR(Dashboard!$C$13="All",A11=Dashboard!$C$13),OR(Dashboard!$C$14="All",B11=Dashboard!$C$14),OR(Dashboard!$C$16="All",K11=Dashboard!$C$16),OR(Dashboard!$C$17="All",J11=Dashboard!$C$17)),1,0) -> 1 | O11: =IF(AND(L11=1,OR(Dashboard!$C$13="All",A11=Dashboard!$C$13),OR(Dashboard!$C$15="All",C11=Dashboard!$C$15),OR(Dashboard!$C$16="All",K11=Dashboard!$C$16),OR(Dashboard!$C$17="All",J11=Dashboard!$C$17)),1,0) -> 1 | P11: =IF(AND(L11=1,OR(Dashboard!$C$13="All",A11=Dashboard!$C$13),OR(Dashboard!$C$14="All",B11=Dashboard!$C$14),OR(Dashboard!$C$15="All",C11=Dashboard!$C$15),OR(Dashboard!$C$17="All",J11=Dashboard!$C$17)),1,0) -> 1 | Q11: =IF(AND(L11=1,OR(Dashboard!$C$14="All",B11=Dashboard!$C$14),OR(Dashboard!$C$15="All",C11=Dashboard!$C$15),OR(Dashboard!$C$16="All",K11=Dashboard!$C$16),OR(Dashboard!$C$17="All",J11=Dashboard!$C$17)),1,0) -> 1 | R11: =IF(AND(L11=1,OR(Dashboard!$C$13="All",A11=Dashboard!$C$13),OR(Dashboard!$C$14="All",B11=Dashboard!$C$14),OR(Dashboard!$C$15="All",C11=Dashboard!$C$15),OR(Dashboard!$C$16="All",K11=Dashboard!$C$16)),1,0) -> 1 | S11: =IF(M11=1,ROW()-1,"") -> 10 | T11: El Kasr Jewelry | U11: FEIG | V11: [4127.001.01] ID ISC.LRU1002-EU Fixed UHF Long Range Reader (ID LRU1002-EU)
A12: El Kasr | B12: El Nekheely | C12: Ribbons | D12: 20 | E12: 36 | F12: =IF(E12="","",D12*E12) -> 720 | G12: 46154 | H12: 7 | I12: =IF(OR(G12="",H12=""),"",G12+H12*7) -> 46203 | J12: Not Paid | K12: Delayed | L12: =IF(A12="","",IF(OR(G12="",AND(G12>=Dashboard!$C$18,G12<=Dashboard!$C$19)),1,0)) -> 1 | M12: =IF(AND(L12=1,OR(Dashboard!$C$13="All",A12=Dashboard!$C$13),OR(Dashboard!$C$14="All",B12=Dashboard!$C$14),OR(Dashboard!$C$15="All",C12=Dashboard!$C$15),OR(Dashboard!$C$16="All",K12=Dashboard!$C$16),OR(Dashboard!$C$17="All",J12=Dashboard!$C$17)),1,0) -> 1 | N12: =IF(AND(L12=1,OR(Dashboard!$C$13="All",A12=Dashboard!$C$13),OR(Dashboard!$C$14="All",B12=Dashboard!$C$14),OR(Dashboard!$C$16="All",K12=Dashboard!$C$16),OR(Dashboard!$C$17="All",J12=Dashboard!$C$17)),1,0) -> 1 | O12: =IF(AND(L12=1,OR(Dashboard!$C$13="All",A12=Dashboard!$C$13),OR(Dashboard!$C$15="All",C12=Dashboard!$C$15),OR(Dashboard!$C$16="All",K12=Dashboard!$C$16),OR(Dashboard!$C$17="All",J12=Dashboard!$C$17)),1,0) -> 1 | P12: =IF(AND(L12=1,OR(Dashboard!$C$13="All",A12=Dashboard!$C$13),OR(Dashboard!$C$14="All",B12=Dashboard!$C$14),OR(Dashboard!$C$15="All",C12=Dashboard!$C$15),OR(Dashboard!$C$17="All",J12=Dashboard!$C$17)),1,0) -> 1 | Q12: =IF(AND(L12=1,OR(Dashboard!$C$14="All",B12=Dashboard!$C$14),OR(Dashboard!$C$15="All",C12=Dashboard!$C$15),OR(Dashboard!$C$16="All",K12=Dashboard!$C$16),OR(Dashboard!$C$17="All",J12=Dashboard!$C$17)),1,0) -> 1 | R12: =IF(AND(L12=1,OR(Dashboard!$C$13="All",A12=Dashboard!$C$13),OR(Dashboard!$C$14="All",B12=Dashboard!$C$14),OR(Dashboard!$C$15="All",C12=Dashboard!$C$15),OR(Dashboard!$C$16="All",K12=Dashboard!$C$16)),1,0) -> 1 | S12: =IF(M12=1,ROW()-1,"") -> 11 | T12: El Patio | U12: Feig | V12: [4245985] GR, EXT release standard 615
A13: El Kasr | B13: FAAC | C13: LRU1002 | D13: 5 | E13: 95 | F13: =IF(E13="","",D13*E13) -> 475 | G13: 46155 | H13: 2 | I13: =IF(OR(G13="",H13=""),"",G13+H13*7) -> 46169 | J13: Advance Payment | K13: Pending | L13: =IF(A13="","",IF(OR(G13="",AND(G13>=Dashboard!$C$18,G13<=Dashboard!$C$19)),1,0)) -> 1 | M13: =IF(AND(L13=1,OR(Dashboard!$C$13="All",A13=Dashboard!$C$13),OR(Dashboard!$C$14="All",B13=Dashboard!$C$14),OR(Dashboard!$C$15="All",C13=Dashboard!$C$15),OR(Dashboard!$C$16="All",K13=Dashboard!$C$16),OR(Dashboard!$C$17="All",J13=Dashboard!$C$17)),1,0) -> 1 | N13: =IF(AND(L13=1,OR(Dashboard!$C$13="All",A13=Dashboard!$C$13),OR(Dashboard!$C$14="All",B13=Dashboard!$C$14),OR(Dashboard!$C$16="All",K13=Dashboard!$C$16),OR(Dashboard!$C$17="All",J13=Dashboard!$C$17)),1,0) -> 1 | O13: =IF(AND(L13=1,OR(Dashboard!$C$13="All",A13=Dashboard!$C$13),OR(Dashboard!$C$15="All",C13=Dashboard!$C$15),OR(Dashboard!$C$16="All",K13=Dashboard!$C$16),OR(Dashboard!$C$17="All",J13=Dashboard!$C$17)),1,0) -> 1 | P13: =IF(AND(L13=1,OR(Dashboard!$C$13="All",A13=Dashboard!$C$13),OR(Dashboard!$C$14="All",B13=Dashboard!$C$14),OR(Dashboard!$C$15="All",C13=Dashboard!$C$15),OR(Dashboard!$C$17="All",J13=Dashboard!$C$17)),1,0) -> 1 | Q13: =IF(AND(L13=1,OR(Dashboard!$C$14="All",B13=Dashboard!$C$14),OR(Dashboard!$C$15="All",C13=Dashboard!$C$15),OR(Dashboard!$C$16="All",K13=Dashboard!$C$16),OR(Dashboard!$C$17="All",J13=Dashboard!$C$17)),1,0) -> 1 | R13: =IF(AND(L13=1,OR(Dashboard!$C$13="All",A13=Dashboard!$C$13),OR(Dashboard!$C$14="All",B13=Dashboard!$C$14),OR(Dashboard!$C$15="All",C13=Dashboard!$C$15),OR(Dashboard!$C$16="All",K13=Dashboard!$C$16)),1,0) -> 1 | S13: =IF(M13=1,ROW()-1,"") -> 12 | T13: Bellagio | U13: Fusion | V13: [5118.001.01] ID MAX.U500i-EU
A14: El Kasr | B14: Cube | C14: Antenna | D14: 10 | E14: 574 | F14: =IF(E14="","",D14*E14) -> 5740 | G14: 46156 | H14: 6 | I14: =IF(OR(G14="",H14=""),"",G14+H14*7) -> 46198 | J14: Fully Paid | K14: Pending | L14: =IF(A14="","",IF(OR(G14="",AND(G14>=Dashboard!$C$18,G14<=Dashboard!$C$19)),1,0)) -> 1 | M14: =IF(AND(L14=1,OR(Dashboard!$C$13="All",A14=Dashboard!$C$13),OR(Dashboard!$C$14="All",B14=Dashboard!$C$14),OR(Dashboard!$C$15="All",C14=Dashboard!$C$15),OR(Dashboard!$C$16="All",K14=Dashboard!$C$16),OR(Dashboard!$C$17="All",J14=Dashboard!$C$17)),1,0) -> 1 | N14: =IF(AND(L14=1,OR(Dashboard!$C$13="All",A14=Dashboard!$C$13),OR(Dashboard!$C$14="All",B14=Dashboard!$C$14),OR(Dashboard!$C$16="All",K14=Dashboard!$C$16),OR(Dashboard!$C$17="All",J14=Dashboard!$C$17)),1,0) -> 1 | O14: =IF(AND(L14=1,OR(Dashboard!$C$13="All",A14=Dashboard!$C$13),OR(Dashboard!$C$15="All",C14=Dashboard!$C$15),OR(Dashboard!$C$16="All",K14=Dashboard!$C$16),OR(Dashboard!$C$17="All",J14=Dashboard!$C$17)),1,0) -> 1 | P14: =IF(AND(L14=1,OR(Dashboard!$C$13="All",A14=Dashboard!$C$13),OR(Dashboard!$C$14="All",B14=Dashboard!$C$14),OR(Dashboard!$C$15="All",C14=Dashboard!$C$15),OR(Dashboard!$C$17="All",J14=Dashboard!$C$17)),1,0) -> 1 | Q14: =IF(AND(L14=1,OR(Dashboard!$C$14="All",B14=Dashboard!$C$14),OR(Dashboard!$C$15="All",C14=Dashboard!$C$15),OR(Dashboard!$C$16="All",K14=Dashboard!$C$16),OR(Dashboard!$C$17="All",J14=Dashboard!$C$17)),1,0) -> 1 | R14: =IF(AND(L14=1,OR(Dashboard!$C$13="All",A14=Dashboard!$C$13),OR(Dashboard!$C$14="All",B14=Dashboard!$C$14),OR(Dashboard!$C$15="All",C14=Dashboard!$C$15),OR(Dashboard!$C$16="All",K14=Dashboard!$C$16)),1,0) -> 1 | S14: =IF(M14=1,ROW()-1,"") -> 13 | T14: AlBurouj | U14: IPS | V14: [5118.001.01] ID MAX.U500i-EU Compact UHF Access Control Re
A15: El Kasr | B15: Confidex | C15: AT907 | E15: 558 | F15: =IF(E15="","",D15*E15) -> 0 | G15: 46157 | H15: 4 | I15: =IF(OR(G15="",H15=""),"",G15+H15*7) -> 46185 | J15: Advance Payment | K15: Pending | L15: =IF(A15="","",IF(OR(G15="",AND(G15>=Dashboard!$C$18,G15<=Dashboard!$C$19)),1,0)) -> 1 | M15: =IF(AND(L15=1,OR(Dashboard!$C$13="All",A15=Dashboard!$C$13),OR(Dashboard!$C$14="All",B15=Dashboard!$C$14),OR(Dashboard!$C$15="All",C15=Dashboard!$C$15),OR(Dashboard!$C$16="All",K15=Dashboard!$C$16),OR(Dashboard!$C$17="All",J15=Dashboard!$C$17)),1,0) -> 1 | N15: =IF(AND(L15=1,OR(Dashboard!$C$13="All",A15=Dashboard!$C$13),OR(Dashboard!$C$14="All",B15=Dashboard!$C$14),OR(Dashboard!$C$16="All",K15=Dashboard!$C$16),OR(Dashboard!$C$17="All",J15=Dashboard!$C$17)),1,0) -> 1 | O15: =IF(AND(L15=1,OR(Dashboard!$C$13="All",A15=Dashboard!$C$13),OR(Dashboard!$C$15="All",C15=Dashboard!$C$15),OR(Dashboard!$C$16="All",K15=Dashboard!$C$16),OR(Dashboard!$C$17="All",J15=Dashboard!$C$17)),1,0) -> 1 | P15: =IF(AND(L15=1,OR(Dashboard!$C$13="All",A15=Dashboard!$C$13),OR(Dashboard!$C$14="All",B15=Dashboard!$C$14),OR(Dashboard!$C$15="All",C15=Dashboard!$C$15),OR(Dashboard!$C$17="All",J15=Dashboard!$C$17)),1,0) -> 1 | Q15: =IF(AND(L15=1,OR(Dashboard!$C$14="All",B15=Dashboard!$C$14),OR(Dashboard!$C$15="All",C15=Dashboard!$C$15),OR(Dashboard!$C$16="All",K15=Dashboard!$C$16),OR(Dashboard!$C$17="All",J15=Dashboard!$C$17)),1,0) -> 1 | R15: =IF(AND(L15=1,OR(Dashboard!$C$13="All",A15=Dashboard!$C$13),OR(Dashboard!$C$14="All",B15=Dashboard!$C$14),OR(Dashboard!$C$15="All",C15=Dashboard!$C$15),OR(Dashboard!$C$16="All",K15=Dashboard!$C$16)),1,0) -> 1 | S15: =IF(M15=1,ROW()-1,"") -> 14 | T15: Suez Canal Bank | U15: Jarltech | V15: [5118.001.01] ID MAX.U500i-EU Compact UHF Access Control Reader with integrated Antenna
A16: Harvest | B16: koodle | C16: RFID Desktop Printer with Feeder- (CT4LX) | D16: 2 | E16: 2265 | F16: =IF(E16="","",D16*E16) -> 4530 | G16: 46158 | H16: 1 | I16: =IF(OR(G16="",H16=""),"",G16+H16*7) -> 46165 | J16: Fully Paid | K16: Pending | L16: =IF(A16="","",IF(OR(G16="",AND(G16>=Dashboard!$C$18,G16<=Dashboard!$C$19)),1,0)) -> 1 | M16: =IF(AND(L16=1,OR(Dashboard!$C$13="All",A16=Dashboard!$C$13),OR(Dashboard!$C$14="All",B16=Dashboard!$C$14),OR(Dashboard!$C$15="All",C16=Dashboard!$C$15),OR(Dashboard!$C$16="All",K16=Dashboard!$C$16),OR(Dashboard!$C$17="All",J16=Dashboard!$C$17)),1,0) -> 1 | N16: =IF(AND(L16=1,OR(Dashboard!$C$13="All",A16=Dashboard!$C$13),OR(Dashboard!$C$14="All",B16=Dashboard!$C$14),OR(Dashboard!$C$16="All",K16=Dashboard!$C$16),OR(Dashboard!$C$17="All",J16=Dashboard!$C$17)),1,0) -> 1 | O16: =IF(AND(L16=1,OR(Dashboard!$C$13="All",A16=Dashboard!$C$13),OR(Dashboard!$C$15="All",C16=Dashboard!$C$15),OR(Dashboard!$C$16="All",K16=Dashboard!$C$16),OR(Dashboard!$C$17="All",J16=Dashboard!$C$17)),1,0) -> 1 | P16: =IF(AND(L16=1,OR(Dashboard!$C$13="All",A16=Dashboard!$C$13),OR(Dashboard!$C$14="All",B16=Dashboard!$C$14),OR(Dashboard!$C$15="All",C16=Dashboard!$C$15),OR(Dashboard!$C$17="All",J16=Dashboard!$C$17)),1,0) -> 1 | Q16: =IF(AND(L16=1,OR(Dashboard!$C$14="All",B16=Dashboard!$C$14),OR(Dashboard!$C$15="All",C16=Dashboard!$C$15),OR(Dashboard!$C$16="All",K16=Dashboard!$C$16),OR(Dashboard!$C$17="All",J16=Dashboard!$C$17)),1,0) -> 1 | R16: =IF(AND(L16=1,OR(Dashboard!$C$13="All",A16=Dashboard!$C$13),OR(Dashboard!$C$14="All",B16=Dashboard!$C$14),OR(Dashboard!$C$15="All",C16=Dashboard!$C$15),OR(Dashboard!$C$16="All",K16=Dashboard!$C$16)),1,0) -> 1 | S16: =IF(M16=1,ROW()-1,"") -> 15 | T16: Akoya | U16: jarltech | V16: [5400.001.01] ID ANT1710/690-A Crystal Gate Wave "Base"
A17: Harvest | B17: The tag factory | C17: Ribbons for the printer | D17: 9 | E17: 45 | F17: =IF(E17="","",D17*E17) -> 405 | G17: 46159 | H17: 2 | I17: =IF(OR(G17="",H17=""),"",G17+H17*7) -> 46173 | J17: Not Paid | K17: Pending | L17: =IF(A17="","",IF(OR(G17="",AND(G17>=Dashboard!$C$18,G17<=Dashboard!$C$19)),1,0)) -> 1 | M17: =IF(AND(L17=1,OR(Dashboard!$C$13="All",A17=Dashboard!$C$13),OR(Dashboard!$C$14="All",B17=Dashboard!$C$14),OR(Dashboard!$C$15="All",C17=Dashboard!$C$15),OR(Dashboard!$C$16="All",K17=Dashboard!$C$16),OR(Dashboard!$C$17="All",J17=Dashboard!$C$17)),1,0) -> 1 | N17: =IF(AND(L17=1,OR(Dashboard!$C$13="All",A17=Dashboard!$C$13),OR(Dashboard!$C$14="All",B17=Dashboard!$C$14),OR(Dashboard!$C$16="All",K17=Dashboard!$C$16),OR(Dashboard!$C$17="All",J17=Dashboard!$C$17)),1,0) -> 1 | O17: =IF(AND(L17=1,OR(Dashboard!$C$13="All",A17=Dashboard!$C$13),OR(Dashboard!$C$15="All",C17=Dashboard!$C$15),OR(Dashboard!$C$16="All",K17=Dashboard!$C$16),OR(Dashboard!$C$17="All",J17=Dashboard!$C$17)),1,0) -> 1 | P17: =IF(AND(L17=1,OR(Dashboard!$C$13="All",A17=Dashboard!$C$13),OR(Dashboard!$C$14="All",B17=Dashboard!$C$14),OR(Dashboard!$C$15="All",C17=Dashboard!$C$15),OR(Dashboard!$C$17="All",J17=Dashboard!$C$17)),1,0) -> 1 | Q17: =IF(AND(L17=1,OR(Dashboard!$C$14="All",B17=Dashboard!$C$14),OR(Dashboard!$C$15="All",C17=Dashboard!$C$15),OR(Dashboard!$C$16="All",K17=Dashboard!$C$16),OR(Dashboard!$C$17="All",J17=Dashboard!$C$17)),1,0) -> 1 | R17: =IF(AND(L17=1,OR(Dashboard!$C$13="All",A17=Dashboard!$C$13),OR(Dashboard!$C$14="All",B17=Dashboard!$C$14),OR(Dashboard!$C$15="All",C17=Dashboard!$C$15),OR(Dashboard!$C$16="All",K17=Dashboard!$C$16)),1,0) -> 1 | S17: =IF(M17=1,ROW()-1,"") -> 16 | T17: Marshmallow | U17: koodle | V17: [5401.001.01] ID ANT1710/690-B Crystal Gate Wave
A18: Harvest | B18: Confidex | C18: AT907 | D18: 2 | E18: 5554 | F18: =IF(E18="","",D18*E18) -> 11108 | G18: 46160 | H18: 4 | I18: =IF(OR(G18="",H18=""),"",G18+H18*7) -> 46188 | J18: Not Paid | K18: Completed | L18: =IF(A18="","",IF(OR(G18="",AND(G18>=Dashboard!$C$18,G18<=Dashboard!$C$19)),1,0)) -> 1 | M18: =IF(AND(L18=1,OR(Dashboard!$C$13="All",A18=Dashboard!$C$13),OR(Dashboard!$C$14="All",B18=Dashboard!$C$14),OR(Dashboard!$C$15="All",C18=Dashboard!$C$15),OR(Dashboard!$C$16="All",K18=Dashboard!$C$16),OR(Dashboard!$C$17="All",J18=Dashboard!$C$17)),1,0) -> 1 | N18: =IF(AND(L18=1,OR(Dashboard!$C$13="All",A18=Dashboard!$C$13),OR(Dashboard!$C$14="All",B18=Dashboard!$C$14),OR(Dashboard!$C$16="All",K18=Dashboard!$C$16),OR(Dashboard!$C$17="All",J18=Dashboard!$C$17)),1,0) -> 1 | O18: =IF(AND(L18=1,OR(Dashboard!$C$13="All",A18=Dashboard!$C$13),OR(Dashboard!$C$15="All",C18=Dashboard!$C$15),OR(Dashboard!$C$16="All",K18=Dashboard!$C$16),OR(Dashboard!$C$17="All",J18=Dashboard!$C$17)),1,0) -> 1 | P18: =IF(AND(L18=1,OR(Dashboard!$C$13="All",A18=Dashboard!$C$13),OR(Dashboard!$C$14="All",B18=Dashboard!$C$14),OR(Dashboard!$C$15="All",C18=Dashboard!$C$15),OR(Dashboard!$C$17="All",J18=Dashboard!$C$17)),1,0) -> 1 | Q18: =IF(AND(L18=1,OR(Dashboard!$C$14="All",B18=Dashboard!$C$14),OR(Dashboard!$C$15="All",C18=Dashboard!$C$15),OR(Dashboard!$C$16="All",K18=Dashboard!$C$16),OR(Dashboard!$C$17="All",J18=Dashboard!$C$17)),1,0) -> 1 | R18: =IF(AND(L18=1,OR(Dashboard!$C$13="All",A18=Dashboard!$C$13),OR(Dashboard!$C$14="All",B18=Dashboard!$C$14),OR(Dashboard!$C$15="All",C18=Dashboard!$C$15),OR(Dashboard!$C$16="All",K18=Dashboard!$C$16)),1,0) -> 1 | S18: =IF(M18=1,ROW()-1,"") -> 17 | T18: Karma | U18: Koodle | V18: [7080435] cylinder joint 615
A19: Harvest | B19: Wireless dynamics | C19: Dogbone tags | D19: 20198 | E19: 41 | F19: =IF(E19="","",D19*E19) -> 828118 | G19: 46161 | H19: 6 | I19: =IF(OR(G19="",H19=""),"",G19+H19*7) -> 46203 | J19: Advance Payment | K19: Pending | L19: =IF(A19="","",IF(OR(G19="",AND(G19>=Dashboard!$C$18,G19<=Dashboard!$C$19)),1,0)) -> 1 | M19: =IF(AND(L19=1,OR(Dashboard!$C$13="All",A19=Dashboard!$C$13),OR(Dashboard!$C$14="All",B19=Dashboard!$C$14),OR(Dashboard!$C$15="All",C19=Dashboard!$C$15),OR(Dashboard!$C$16="All",K19=Dashboard!$C$16),OR(Dashboard!$C$17="All",J19=Dashboard!$C$17)),1,0) -> 1 | N19: =IF(AND(L19=1,OR(Dashboard!$C$13="All",A19=Dashboard!$C$13),OR(Dashboard!$C$14="All",B19=Dashboard!$C$14),OR(Dashboard!$C$16="All",K19=Dashboard!$C$16),OR(Dashboard!$C$17="All",J19=Dashboard!$C$17)),1,0) -> 1 | O19: =IF(AND(L19=1,OR(Dashboard!$C$13="All",A19=Dashboard!$C$13),OR(Dashboard!$C$15="All",C19=Dashboard!$C$15),OR(Dashboard!$C$16="All",K19=Dashboard!$C$16),OR(Dashboard!$C$17="All",J19=Dashboard!$C$17)),1,0) -> 1 | P19: =IF(AND(L19=1,OR(Dashboard!$C$13="All",A19=Dashboard!$C$13),OR(Dashboard!$C$14="All",B19=Dashboard!$C$14),OR(Dashboard!$C$15="All",C19=Dashboard!$C$15),OR(Dashboard!$C$17="All",J19=Dashboard!$C$17)),1,0) -> 1 | Q19: =IF(AND(L19=1,OR(Dashboard!$C$14="All",B19=Dashboard!$C$14),OR(Dashboard!$C$15="All",C19=Dashboard!$C$15),OR(Dashboard!$C$16="All",K19=Dashboard!$C$16),OR(Dashboard!$C$17="All",J19=Dashboard!$C$17)),1,0) -> 1 | R19: =IF(AND(L19=1,OR(Dashboard!$C$13="All",A19=Dashboard!$C$13),OR(Dashboard!$C$14="All",B19=Dashboard!$C$14),OR(Dashboard!$C$15="All",C19=Dashboard!$C$15),OR(Dashboard!$C$16="All",K19=Dashboard!$C$16)),1,0) -> 1 | S19: =IF(M19=1,ROW()-1,"") -> 18 | T19: Geera | U19: Local | V19: [7128035] cylinder lock
A20: Harvest | B20: Metalcraft | C20: EU Universal tags- Blank | D20: 1069 | E20: 231 | F20: =IF(E20="","",D20*E20) -> 246939 | G20: 46162 | H20: 8 | I20: =IF(OR(G20="",H20=""),"",G20+H20*7) -> 46218 | J20: Fully Paid | K20: In Progress | L20: =IF(A20="","",IF(OR(G20="",AND(G20>=Dashboard!$C$18,G20<=Dashboard!$C$19)),1,0)) -> 1 | M20: =IF(AND(L20=1,OR(Dashboard!$C$13="All",A20=Dashboard!$C$13),OR(Dashboard!$C$14="All",B20=Dashboard!$C$14),OR(Dashboard!$C$15="All",C20=Dashboard!$C$15),OR(Dashboard!$C$16="All",K20=Dashboard!$C$16),OR(Dashboard!$C$17="All",J20=Dashboard!$C$17)),1,0) -> 1 | N20: =IF(AND(L20=1,OR(Dashboard!$C$13="All",A20=Dashboard!$C$13),OR(Dashboard!$C$14="All",B20=Dashboard!$C$14),OR(Dashboard!$C$16="All",K20=Dashboard!$C$16),OR(Dashboard!$C$17="All",J20=Dashboard!$C$17)),1,0) -> 1 | O20: =IF(AND(L20=1,OR(Dashboard!$C$13="All",A20=Dashboard!$C$13),OR(Dashboard!$C$15="All",C20=Dashboard!$C$15),OR(Dashboard!$C$16="All",K20=Dashboard!$C$16),OR(Dashboard!$C$17="All",J20=Dashboard!$C$17)),1,0) -> 1 | P20: =IF(AND(L20=1,OR(Dashboard!$C$13="All",A20=Dashboard!$C$13),OR(Dashboard!$C$14="All",B20=Dashboard!$C$14),OR(Dashboard!$C$15="All",C20=Dashboard!$C$15),OR(Dashboard!$C$17="All",J20=Dashboard!$C$17)),1,0) -> 1 | Q20: =IF(AND(L20=1,OR(Dashboard!$C$14="All",B20=Dashboard!$C$14),OR(Dashboard!$C$15="All",C20=Dashboard!$C$15),OR(Dashboard!$C$16="All",K20=Dashboard!$C$16),OR(Dashboard!$C$17="All",J20=Dashboard!$C$17)),1,0) -> 1 | R20: =IF(AND(L20=1,OR(Dashboard!$C$13="All",A20=Dashboard!$C$13),OR(Dashboard!$C$14="All",B20=Dashboard!$C$14),OR(Dashboard!$C$15="All",C20=Dashboard!$C$15),OR(Dashboard!$C$16="All",K20=Dashboard!$C$16)),1,0) -> 1 | S20: =IF(M20=1,ROW()-1,"") -> 19 | T20: Jewar | U20: Metalcraft | V20: [713002] 402 release key
A21: Harvest | B21: zebra | C21: Hang tags | D21: 447 | E21: 25 | F21: =IF(E21="","",D21*E21) -> 11175 | G21: 46163 | H21: 9 | I21: =IF(OR(G21="",H21=""),"",G21+H21*7) -> 46226 | J21: Advance Payment | K21: Completed | L21: =IF(A21="","",IF(OR(G21="",AND(G21>=Dashboard!$C$18,G21<=Dashboard!$C$19)),1,0)) -> 1 | M21: =IF(AND(L21=1,OR(Dashboard!$C$13="All",A21=Dashboard!$C$13),OR(Dashboard!$C$14="All",B21=Dashboard!$C$14),OR(Dashboard!$C$15="All",C21=Dashboard!$C$15),OR(Dashboard!$C$16="All",K21=Dashboard!$C$16),OR(Dashboard!$C$17="All",J21=Dashboard!$C$17)),1,0) -> 1 | N21: =IF(AND(L21=1,OR(Dashboard!$C$13="All",A21=Dashboard!$C$13),OR(Dashboard!$C$14="All",B21=Dashboard!$C$14),OR(Dashboard!$C$16="All",K21=Dashboard!$C$16),OR(Dashboard!$C$17="All",J21=Dashboard!$C$17)),1,0) -> 1 | O21: =IF(AND(L21=1,OR(Dashboard!$C$13="All",A21=Dashboard!$C$13),OR(Dashboard!$C$15="All",C21=Dashboard!$C$15),OR(Dashboard!$C$16="All",K21=Dashboard!$C$16),OR(Dashboard!$C$17="All",J21=Dashboard!$C$17)),1,0) -> 1 | P21: =IF(AND(L21=1,OR(Dashboard!$C$13="All",A21=Dashboard!$C$13),OR(Dashboard!$C$14="All",B21=Dashboard!$C$14),OR(Dashboard!$C$15="All",C21=Dashboard!$C$15),OR(Dashboard!$C$17="All",J21=Dashboard!$C$17)),1,0) -> 1 | Q21: =IF(AND(L21=1,OR(Dashboard!$C$14="All",B21=Dashboard!$C$14),OR(Dashboard!$C$15="All",C21=Dashboard!$C$15),OR(Dashboard!$C$16="All",K21=Dashboard!$C$16),OR(Dashboard!$C$17="All",J21=Dashboard!$C$17)),1,0) -> 1 | R21: =IF(AND(L21=1,OR(Dashboard!$C$13="All",A21=Dashboard!$C$13),OR(Dashboard!$C$14="All",B21=Dashboard!$C$14),OR(Dashboard!$C$15="All",C21=Dashboard!$C$15),OR(Dashboard!$C$16="All",K21=Dashboard!$C$16)),1,0) -> 1 | S21: =IF(M21=1,ROW()-1,"") -> 20 | T21: El Nakheel | U21: Metalcraft/ Thabet | V21: [ACG8065] Pair of columns for FIT SLIM photocells
A22: Harvest | B22: The tag factory | C22: Dest windshield tags | D22: 482 | E22: 245 | F22: =IF(E22="","",D22*E22) -> 118090 | G22: 46164 | H22: 4 | I22: =IF(OR(G22="",H22=""),"",G22+H22*7) -> 46192 | J22: Fully Paid | K22: Delayed | L22: =IF(A22="","",IF(OR(G22="",AND(G22>=Dashboard!$C$18,G22<=Dashboard!$C$19)),1,0)) -> 1 | M22: =IF(AND(L22=1,OR(Dashboard!$C$13="All",A22=Dashboard!$C$13),OR(Dashboard!$C$14="All",B22=Dashboard!$C$14),OR(Dashboard!$C$15="All",C22=Dashboard!$C$15),OR(Dashboard!$C$16="All",K22=Dashboard!$C$16),OR(Dashboard!$C$17="All",J22=Dashboard!$C$17)),1,0) -> 1 | N22: =IF(AND(L22=1,OR(Dashboard!$C$13="All",A22=Dashboard!$C$13),OR(Dashboard!$C$14="All",B22=Dashboard!$C$14),OR(Dashboard!$C$16="All",K22=Dashboard!$C$16),OR(Dashboard!$C$17="All",J22=Dashboard!$C$17)),1,0) -> 1 | O22: =IF(AND(L22=1,OR(Dashboard!$C$13="All",A22=Dashboard!$C$13),OR(Dashboard!$C$15="All",C22=Dashboard!$C$15),OR(Dashboard!$C$16="All",K22=Dashboard!$C$16),OR(Dashboard!$C$17="All",J22=Dashboard!$C$17)),1,0) -> 1 | P22: =IF(AND(L22=1,OR(Dashboard!$C$13="All",A22=Dashboard!$C$13),OR(Dashboard!$C$14="All",B22=Dashboard!$C$14),OR(Dashboard!$C$15="All",C22=Dashboard!$C$15),OR(Dashboard!$C$17="All",J22=Dashboard!$C$17)),1,0) -> 1 | Q22: =IF(AND(L22=1,OR(Dashboard!$C$14="All",B22=Dashboard!$C$14),OR(Dashboard!$C$15="All",C22=Dashboard!$C$15),OR(Dashboard!$C$16="All",K22=Dashboard!$C$16),OR(Dashboard!$C$17="All",J22=Dashboard!$C$17)),1,0) -> 1 | R22: =IF(AND(L22=1,OR(Dashboard!$C$13="All",A22=Dashboard!$C$13),OR(Dashboard!$C$14="All",B22=Dashboard!$C$14),OR(Dashboard!$C$15="All",C22=Dashboard!$C$15),OR(Dashboard!$C$16="All",K22=Dashboard!$C$16)),1,0) -> 1 | S22: =IF(M22=1,ROW()-1,"") -> 21 | T22: Radisson Blue | U22: Minamark | V22: [ACG8502] RIB Boom arm 4 m. - Ø80mm
A23: Lavista Patios | B23: Rich | C23: Dest windshield tags | D23: 500 | E23: 2555 | F23: =IF(E23="","",D23*E23) -> 1277500 | G23: 46165 | H23: 3 | I23: =IF(OR(G23="",H23=""),"",G23+H23*7) -> 46186 | J23: Not Paid | K23: Pending | L23: =IF(A23="","",IF(OR(G23="",AND(G23>=Dashboard!$C$18,G23<=Dashboard!$C$19)),1,0)) -> 1 | M23: =IF(AND(L23=1,OR(Dashboard!$C$13="All",A23=Dashboard!$C$13),OR(Dashboard!$C$14="All",B23=Dashboard!$C$14),OR(Dashboard!$C$15="All",C23=Dashboard!$C$15),OR(Dashboard!$C$16="All",K23=Dashboard!$C$16),OR(Dashboard!$C$17="All",J23=Dashboard!$C$17)),1,0) -> 1 | N23: =IF(AND(L23=1,OR(Dashboard!$C$13="All",A23=Dashboard!$C$13),OR(Dashboard!$C$14="All",B23=Dashboard!$C$14),OR(Dashboard!$C$16="All",K23=Dashboard!$C$16),OR(Dashboard!$C$17="All",J23=Dashboard!$C$17)),1,0) -> 1 | O23: =IF(AND(L23=1,OR(Dashboard!$C$13="All",A23=Dashboard!$C$13),OR(Dashboard!$C$15="All",C23=Dashboard!$C$15),OR(Dashboard!$C$16="All",K23=Dashboard!$C$16),OR(Dashboard!$C$17="All",J23=Dashboard!$C$17)),1,0) -> 1 | P23: =IF(AND(L23=1,OR(Dashboard!$C$13="All",A23=Dashboard!$C$13),OR(Dashboard!$C$14="All",B23=Dashboard!$C$14),OR(Dashboard!$C$15="All",C23=Dashboard!$C$15),OR(Dashboard!$C$17="All",J23=Dashboard!$C$17)),1,0) -> 1 | Q23: =IF(AND(L23=1,OR(Dashboard!$C$14="All",B23=Dashboard!$C$14),OR(Dashboard!$C$15="All",C23=Dashboard!$C$15),OR(Dashboard!$C$16="All",K23=Dashboard!$C$16),OR(Dashboard!$C$17="All",J23=Dashboard!$C$17)),1,0) -> 1 | R23: =IF(AND(L23=1,OR(Dashboard!$C$13="All",A23=Dashboard!$C$13),OR(Dashboard!$C$14="All",B23=Dashboard!$C$14),OR(Dashboard!$C$15="All",C23=Dashboard!$C$15),OR(Dashboard!$C$16="All",K23=Dashboard!$C$16)),1,0) -> 1 | S23: =IF(M23=1,ROW()-1,"") -> 22 | T23: Prometeon | U23: OGTech Dubai | V23: [BA04011] Mechanical Stopper
A24: Layan | B24: Metalcraft | C24: Dest windshield tags | D24: 5000 | E24: 255 | F24: =IF(E24="","",D24*E24) -> 1275000 | G24: 46166 | H24: 1 | I24: =IF(OR(G24="",H24=""),"",G24+H24*7) -> 46173 | J24: Not Paid | K24: Pending | L24: =IF(A24="","",IF(OR(G24="",AND(G24>=Dashboard!$C$18,G24<=Dashboard!$C$19)),1,0)) -> 1 | M24: =IF(AND(L24=1,OR(Dashboard!$C$13="All",A24=Dashboard!$C$13),OR(Dashboard!$C$14="All",B24=Dashboard!$C$14),OR(Dashboard!$C$15="All",C24=Dashboard!$C$15),OR(Dashboard!$C$16="All",K24=Dashboard!$C$16),OR(Dashboard!$C$17="All",J24=Dashboard!$C$17)),1,0) -> 1 | N24: =IF(AND(L24=1,OR(Dashboard!$C$13="All",A24=Dashboard!$C$13),OR(Dashboard!$C$14="All",B24=Dashboard!$C$14),OR(Dashboard!$C$16="All",K24=Dashboard!$C$16),OR(Dashboard!$C$17="All",J24=Dashboard!$C$17)),1,0) -> 1 | O24: =IF(AND(L24=1,OR(Dashboard!$C$13="All",A24=Dashboard!$C$13),OR(Dashboard!$C$15="All",C24=Dashboard!$C$15),OR(Dashboard!$C$16="All",K24=Dashboard!$C$16),OR(Dashboard!$C$17="All",J24=Dashboard!$C$17)),1,0) -> 1 | P24: =IF(AND(L24=1,OR(Dashboard!$C$13="All",A24=Dashboard!$C$13),OR(Dashboard!$C$14="All",B24=Dashboard!$C$14),OR(Dashboard!$C$15="All",C24=Dashboard!$C$15),OR(Dashboard!$C$17="All",J24=Dashboard!$C$17)),1,0) -> 1 | Q24: =IF(AND(L24=1,OR(Dashboard!$C$14="All",B24=Dashboard!$C$14),OR(Dashboard!$C$15="All",C24=Dashboard!$C$15),OR(Dashboard!$C$16="All",K24=Dashboard!$C$16),OR(Dashboard!$C$17="All",J24=Dashboard!$C$17)),1,0) -> 1 | R24: =IF(AND(L24=1,OR(Dashboard!$C$13="All",A24=Dashboard!$C$13),OR(Dashboard!$C$14="All",B24=Dashboard!$C$14),OR(Dashboard!$C$15="All",C24=Dashboard!$C$15),OR(Dashboard!$C$16="All",K24=Dashboard!$C$16)),1,0) -> 1 | S24: =IF(M24=1,ROW()-1,"") -> 23 | T24: SIDC | U24: Perkotek | V24: [CEL1425] Capacitor 230v
A25: Majid El futtaim | B25: OGTech Dubai | C25: MaxU1002 | D25: 1 | E25: 45 | F25: =IF(E25="","",D25*E25) -> 45 | G25: 46167 | H25: 2 | I25: =IF(OR(G25="",H25=""),"",G25+H25*7) -> 46181 | J25: Advance Payment | K25: Pending | L25: =IF(A25="","",IF(OR(G25="",AND(G25>=Dashboard!$C$18,G25<=Dashboard!$C$19)),1,0)) -> 1 | M25: =IF(AND(L25=1,OR(Dashboard!$C$13="All",A25=Dashboard!$C$13),OR(Dashboard!$C$14="All",B25=Dashboard!$C$14),OR(Dashboard!$C$15="All",C25=Dashboard!$C$15),OR(Dashboard!$C$16="All",K25=Dashboard!$C$16),OR(Dashboard!$C$17="All",J25=Dashboard!$C$17)),1,0) -> 1 | N25: =IF(AND(L25=1,OR(Dashboard!$C$13="All",A25=Dashboard!$C$13),OR(Dashboard!$C$14="All",B25=Dashboard!$C$14),OR(Dashboard!$C$16="All",K25=Dashboard!$C$16),OR(Dashboard!$C$17="All",J25=Dashboard!$C$17)),1,0) -> 1 | O25: =IF(AND(L25=1,OR(Dashboard!$C$13="All",A25=Dashboard!$C$13),OR(Dashboard!$C$15="All",C25=Dashboard!$C$15),OR(Dashboard!$C$16="All",K25=Dashboard!$C$16),OR(Dashboard!$C$17="All",J25=Dashboard!$C$17)),1,0) -> 1 | P25: =IF(AND(L25=1,OR(Dashboard!$C$13="All",A25=Dashboard!$C$13),OR(Dashboard!$C$14="All",B25=Dashboard!$C$14),OR(Dashboard!$C$15="All",C25=Dashboard!$C$15),OR(Dashboard!$C$17="All",J25=Dashboard!$C$17)),1,0) -> 1 | Q25: =IF(AND(L25=1,OR(Dashboard!$C$14="All",B25=Dashboard!$C$14),OR(Dashboard!$C$15="All",C25=Dashboard!$C$15),OR(Dashboard!$C$16="All",K25=Dashboard!$C$16),OR(Dashboard!$C$17="All",J25=Dashboard!$C$17)),1,0) -> 1 | R25: =IF(AND(L25=1,OR(Dashboard!$C$13="All",A25=Dashboard!$C$13),OR(Dashboard!$C$14="All",B25=Dashboard!$C$14),OR(Dashboard!$C$15="All",C25=Dashboard!$C$15),OR(Dashboard!$C$16="All",K25=Dashboard!$C$16)),1,0) -> 1 | S25: =IF(M25=1,ROW()-1,"") -> 24 | T25: SLR-RFID | U25: Promojet | V25: [CEL1425] Capacitor 230v
A26: Majid El futtaim | B26: FEIG | C26: Antenna 270/270 U | D26: 2 | E26: 36 | F26: =IF(E26="","",D26*E26) -> 72 | G26: 46168 | H26: 7 | I26: =IF(OR(G26="",H26=""),"",G26+H26*7) -> 46217 | J26: Fully Paid | K26: Completed | L26: =IF(A26="","",IF(OR(G26="",AND(G26>=Dashboard!$C$18,G26<=Dashboard!$C$19)),1,0)) -> 1 | M26: =IF(AND(L26=1,OR(Dashboard!$C$13="All",A26=Dashboard!$C$13),OR(Dashboard!$C$14="All",B26=Dashboard!$C$14),OR(Dashboard!$C$15="All",C26=Dashboard!$C$15),OR(Dashboard!$C$16="All",K26=Dashboard!$C$16),OR(Dashboard!$C$17="All",J26=Dashboard!$C$17)),1,0) -> 1 | N26: =IF(AND(L26=1,OR(Dashboard!$C$13="All",A26=Dashboard!$C$13),OR(Dashboard!$C$14="All",B26=Dashboard!$C$14),OR(Dashboard!$C$16="All",K26=Dashboard!$C$16),OR(Dashboard!$C$17="All",J26=Dashboard!$C$17)),1,0) -> 1 | O26: =IF(AND(L26=1,OR(Dashboard!$C$13="All",A26=Dashboard!$C$13),OR(Dashboard!$C$15="All",C26=Dashboard!$C$15),OR(Dashboard!$C$16="All",K26=Dashboard!$C$16),OR(Dashboard!$C$17="All",J26=Dashboard!$C$17)),1,0) -> 1 | P26: =IF(AND(L26=1,OR(Dashboard!$C$13="All",A26=Dashboard!$C$13),OR(Dashboard!$C$14="All",B26=Dashboard!$C$14),OR(Dashboard!$C$15="All",C26=Dashboard!$C$15),OR(Dashboard!$C$17="All",J26=Dashboard!$C$17)),1,0) -> 1 | Q26: =IF(AND(L26=1,OR(Dashboard!$C$14="All",B26=Dashboard!$C$14),OR(Dashboard!$C$15="All",C26=Dashboard!$C$15),OR(Dashboard!$C$16="All",K26=Dashboard!$C$16),OR(Dashboard!$C$17="All",J26=Dashboard!$C$17)),1,0) -> 1 | R26: =IF(AND(L26=1,OR(Dashboard!$C$13="All",A26=Dashboard!$C$13),OR(Dashboard!$C$14="All",B26=Dashboard!$C$14),OR(Dashboard!$C$15="All",C26=Dashboard!$C$15),OR(Dashboard!$C$16="All",K26=Dashboard!$C$16)),1,0) -> 1 | S26: =IF(M26=1,ROW()-1,"") -> 25 | T26: Enova | U26: RIB | V26: [EG-437750582-001] LF Cards- Printed
A27: Majid El futtaim | B27: Metalcraft | C27: RFID Destructive WINDSHIELD Tags Printed | D27: 50 | E27: 96 | F27: =IF(E27="","",D27*E27) -> 4800 | G27: 46169 | H27: 2 | I27: =IF(OR(G27="",H27=""),"",G27+H27*7) -> 46183 | J27: Advance Payment | K27: Pending | L27: =IF(A27="","",IF(OR(G27="",AND(G27>=Dashboard!$C$18,G27<=Dashboard!$C$19)),1,0)) -> 1 | M27: =IF(AND(L27=1,OR(Dashboard!$C$13="All",A27=Dashboard!$C$13),OR(Dashboard!$C$14="All",B27=Dashboard!$C$14),OR(Dashboard!$C$15="All",C27=Dashboard!$C$15),OR(Dashboard!$C$16="All",K27=Dashboard!$C$16),OR(Dashboard!$C$17="All",J27=Dashboard!$C$17)),1,0) -> 1 | N27: =IF(AND(L27=1,OR(Dashboard!$C$13="All",A27=Dashboard!$C$13),OR(Dashboard!$C$14="All",B27=Dashboard!$C$14),OR(Dashboard!$C$16="All",K27=Dashboard!$C$16),OR(Dashboard!$C$17="All",J27=Dashboard!$C$17)),1,0) -> 1 | O27: =IF(AND(L27=1,OR(Dashboard!$C$13="All",A27=Dashboard!$C$13),OR(Dashboard!$C$15="All",C27=Dashboard!$C$15),OR(Dashboard!$C$16="All",K27=Dashboard!$C$16),OR(Dashboard!$C$17="All",J27=Dashboard!$C$17)),1,0) -> 1 | P27: =IF(AND(L27=1,OR(Dashboard!$C$13="All",A27=Dashboard!$C$13),OR(Dashboard!$C$14="All",B27=Dashboard!$C$14),OR(Dashboard!$C$15="All",C27=Dashboard!$C$15),OR(Dashboard!$C$17="All",J27=Dashboard!$C$17)),1,0) -> 1 | Q27: =IF(AND(L27=1,OR(Dashboard!$C$14="All",B27=Dashboard!$C$14),OR(Dashboard!$C$15="All",C27=Dashboard!$C$15),OR(Dashboard!$C$16="All",K27=Dashboard!$C$16),OR(Dashboard!$C$17="All",J27=Dashboard!$C$17)),1,0) -> 1 | R27: =IF(AND(L27=1,OR(Dashboard!$C$13="All",A27=Dashboard!$C$13),OR(Dashboard!$C$14="All",B27=Dashboard!$C$14),OR(Dashboard!$C$15="All",C27=Dashboard!$C$15),OR(Dashboard!$C$16="All",K27=Dashboard!$C$16)),1,0) -> 1 | S27: =IF(M27=1,ROW()-1,"") -> 26 | T27: Semiramis | U27: Rich | V27: [OG-00170] UHF cards- printed
... A39: El Patio | B39: El Nekheely | C39: Coaxial 13m | D39: 2 | E39: 15 | F39: =IF(E39="","",D39*E39) -> 30 | G39: 46181 | H39: 5 | I39: =IF(OR(G39="",H39=""),"",G39+H39*7) -> 46216 | J39: Not Paid | K39: Completed | L39: =IF(A39="","",IF(OR(G39="",AND(G39>=Dashboard!$C$18,G39<=Dashboard!$C$19)),1,0)) -> 1 | M39: =IF(AND(L39=1,OR(Dashboard!$C$13="All",A39=Dashboard!$C$13),OR(Dashboard!$C$14="All",B39=Dashboard!$C$14),OR(Dashboard!$C$15="All",C39=Dashboard!$C$15),OR(Dashboard!$C$16="All",K39=Dashboard!$C$16),OR(Dashboard!$C$17="All",J39=Dashboard!$C$17)),1,0) -> 1 | N39: =IF(AND(L39=1,OR(Dashboard!$C$13="All",A39=Dashboard!$C$13),OR(Dashboard!$C$14="All",B39=Dashboard!$C$14),OR(Dashboard!$C$16="All",K39=Dashboard!$C$16),OR(Dashboard!$C$17="All",J39=Dashboard!$C$17)),1,0) -> 1 | O39: =IF(AND(L39=1,OR(Dashboard!$C$13="All",A39=Dashboard!$C$13),OR(Dashboard!$C$15="All",C39=Dashboard!$C$15),OR(Dashboard!$C$16="All",K39=Dashboard!$C$16),OR(Dashboard!$C$17="All",J39=Dashboard!$C$17)),1,0) -> 1 | P39: =IF(AND(L39=1,OR(Dashboard!$C$13="All",A39=Dashboard!$C$13),OR(Dashboard!$C$14="All",B39=Dashboard!$C$14),OR(Dashboard!$C$15="All",C39=Dashboard!$C$15),OR(Dashboard!$C$17="All",J39=Dashboard!$C$17)),1,0) -> 1 | Q39: =IF(AND(L39=1,OR(Dashboard!$C$14="All",B39=Dashboard!$C$14),OR(Dashboard!$C$15="All",C39=Dashboard!$C$15),OR(Dashboard!$C$16="All",K39=Dashboard!$C$16),OR(Dashboard!$C$17="All",J39=Dashboard!$C$17)),1,0) -> 1 | R39: =IF(AND(L39=1,OR(Dashboard!$C$13="All",A39=Dashboard!$C$13),OR(Dashboard!$C$14="All",B39=Dashboard!$C$14),OR(Dashboard!$C$15="All",C39=Dashboard!$C$15),OR(Dashboard!$C$16="All",K39=Dashboard!$C$16)),1,0) -> 1 | S39: =IF(M39=1,ROW()-1,"") -> 38 | T39: Obour institute | U39: zebra | V39: [WWCT03243] CT4−LX TT203 RFID UHF Printer
A40: Bellagio | B40: Tech-Electrique | C40: FAAC Gate B614- 4m | D40: 2 | E40: 45 | F40: =IF(E40="","",D40*E40) -> 90 | G40: 46182 | H40: 8 | I40: =IF(OR(G40="",H40=""),"",G40+H40*7) -> 46238 | J40: Not Paid | K40: Delayed | L40: =IF(A40="","",IF(OR(G40="",AND(G40>=Dashboard!$C$18,G40<=Dashboard!$C$19)),1,0)) -> 1 | M40: =IF(AND(L40=1,OR(Dashboard!$C$13="All",A40=Dashboard!$C$13),OR(Dashboard!$C$14="All",B40=Dashboard!$C$14),OR(Dashboard!$C$15="All",C40=Dashboard!$C$15),OR(Dashboard!$C$16="All",K40=Dashboard!$C$16),OR(Dashboard!$C$17="All",J40=Dashboard!$C$17)),1,0) -> 1 | N40: =IF(AND(L40=1,OR(Dashboard!$C$13="All",A40=Dashboard!$C$13),OR(Dashboard!$C$14="All",B40=Dashboard!$C$14),OR(Dashboard!$C$16="All",K40=Dashboard!$C$16),OR(Dashboard!$C$17="All",J40=Dashboard!$C$17)),1,0) -> 1 | O40: =IF(AND(L40=1,OR(Dashboard!$C$13="All",A40=Dashboard!$C$13),OR(Dashboard!$C$15="All",C40=Dashboard!$C$15),OR(Dashboard!$C$16="All",K40=Dashboard!$C$16),OR(Dashboard!$C$17="All",J40=Dashboard!$C$17)),1,0) -> 1 | P40: =IF(AND(L40=1,OR(Dashboard!$C$13="All",A40=Dashboard!$C$13),OR(Dashboard!$C$14="All",B40=Dashboard!$C$14),OR(Dashboard!$C$15="All",C40=Dashboard!$C$15),OR(Dashboard!$C$17="All",J40=Dashboard!$C$17)),1,0) -> 1 | Q40: =IF(AND(L40=1,OR(Dashboard!$C$14="All",B40=Dashboard!$C$14),OR(Dashboard!$C$15="All",C40=Dashboard!$C$15),OR(Dashboard!$C$16="All",K40=Dashboard!$C$16),OR(Dashboard!$C$17="All",J40=Dashboard!$C$17)),1,0) -> 1 | R40: =IF(AND(L40=1,OR(Dashboard!$C$13="All",A40=Dashboard!$C$13),OR(Dashboard!$C$14="All",B40=Dashboard!$C$14),OR(Dashboard!$C$15="All",C40=Dashboard!$C$15),OR(Dashboard!$C$16="All",K40=Dashboard!$C$16)),1,0) -> 1 | S40: =IF(M40=1,ROW()-1,"") -> 39 | T40: Obour university | V40: [WWFX31243] FX3-LX SATO Food Printer
A41: Bellagio | B41: Tech-Electrique | C41: Control Board of Barrier FAAC B614 | D41: 1 | E41: 24 | F41: =IF(E41="","",D41*E41) -> 24 | G41: 46183 | H41: 5 | I41: =IF(OR(G41="",H41=""),"",G41+H41*7) -> 46218 | J41: Not Paid | K41: Pending | L41: =IF(A41="","",IF(OR(G41="",AND(G41>=Dashboard!$C$18,G41<=Dashboard!$C$19)),1,0)) -> 1 | M41: =IF(AND(L41=1,OR(Dashboard!$C$13="All",A41=Dashboard!$C$13),OR(Dashboard!$C$14="All",B41=Dashboard!$C$14),OR(Dashboard!$C$15="All",C41=Dashboard!$C$15),OR(Dashboard!$C$16="All",K41=Dashboard!$C$16),OR(Dashboard!$C$17="All",J41=Dashboard!$C$17)),1,0) -> 1 | N41: =IF(AND(L41=1,OR(Dashboard!$C$13="All",A41=Dashboard!$C$13),OR(Dashboard!$C$14="All",B41=Dashboard!$C$14),OR(Dashboard!$C$16="All",K41=Dashboard!$C$16),OR(Dashboard!$C$17="All",J41=Dashboard!$C$17)),1,0) -> 1 | O41: =IF(AND(L41=1,OR(Dashboard!$C$13="All",A41=Dashboard!$C$13),OR(Dashboard!$C$15="All",C41=Dashboard!$C$15),OR(Dashboard!$C$16="All",K41=Dashboard!$C$16),OR(Dashboard!$C$17="All",J41=Dashboard!$C$17)),1,0) -> 1 | P41: =IF(AND(L41=1,OR(Dashboard!$C$13="All",A41=Dashboard!$C$13),OR(Dashboard!$C$14="All",B41=Dashboard!$C$14),OR(Dashboard!$C$15="All",C41=Dashboard!$C$15),OR(Dashboard!$C$17="All",J41=Dashboard!$C$17)),1,0) -> 1 | Q41: =IF(AND(L41=1,OR(Dashboard!$C$14="All",B41=Dashboard!$C$14),OR(Dashboard!$C$15="All",C41=Dashboard!$C$15),OR(Dashboard!$C$16="All",K41=Dashboard!$C$16),OR(Dashboard!$C$17="All",J41=Dashboard!$C$17)),1,0) -> 1 | R41: =IF(AND(L41=1,OR(Dashboard!$C$13="All",A41=Dashboard!$C$13),OR(Dashboard!$C$14="All",B41=Dashboard!$C$14),OR(Dashboard!$C$15="All",C41=Dashboard!$C$15),OR(Dashboard!$C$16="All",K41=Dashboard!$C$16)),1,0) -> 1 | S41: =IF(M41=1,ROW()-1,"") -> 40 | T41: Tanmyah | V41: [Y10110600011] Special Ribbons for SATO Desktop Printer
A42: AlBurouj | C42: FAAC Boom- 3m | D42: 1 | E42: 25 | F42: =IF(E42="","",D42*E42) -> 25 | G42: 46184 | H42: 6 | I42: =IF(OR(G42="",H42=""),"",G42+H42*7) -> 46226 | J42: Not Paid | K42: Completed | L42: =IF(A42="","",IF(OR(G42="",AND(G42>=Dashboard!$C$18,G42<=Dashboard!$C$19)),1,0)) -> 1 | M42: =IF(AND(L42=1,OR(Dashboard!$C$13="All",A42=Dashboard!$C$13),OR(Dashboard!$C$14="All",B42=Dashboard!$C$14),OR(Dashboard!$C$15="All",C42=Dashboard!$C$15),OR(Dashboard!$C$16="All",K42=Dashboard!$C$16),OR(Dashboard!$C$17="All",J42=Dashboard!$C$17)),1,0) -> 1 | N42: =IF(AND(L42=1,OR(Dashboard!$C$13="All",A42=Dashboard!$C$13),OR(Dashboard!$C$14="All",B42=Dashboard!$C$14),OR(Dashboard!$C$16="All",K42=Dashboard!$C$16),OR(Dashboard!$C$17="All",J42=Dashboard!$C$17)),1,0) -> 1 | O42: =IF(AND(L42=1,OR(Dashboard!$C$13="All",A42=Dashboard!$C$13),OR(Dashboard!$C$15="All",C42=Dashboard!$C$15),OR(Dashboard!$C$16="All",K42=Dashboard!$C$16),OR(Dashboard!$C$17="All",J42=Dashboard!$C$17)),1,0) -> 1 | P42: =IF(AND(L42=1,OR(Dashboard!$C$13="All",A42=Dashboard!$C$13),OR(Dashboard!$C$14="All",B42=Dashboard!$C$14),OR(Dashboard!$C$15="All",C42=Dashboard!$C$15),OR(Dashboard!$C$17="All",J42=Dashboard!$C$17)),1,0) -> 1 | Q42: =IF(AND(L42=1,OR(Dashboard!$C$14="All",B42=Dashboard!$C$14),OR(Dashboard!$C$15="All",C42=Dashboard!$C$15),OR(Dashboard!$C$16="All",K42=Dashboard!$C$16),OR(Dashboard!$C$17="All",J42=Dashboard!$C$17)),1,0) -> 1 | R42: =IF(AND(L42=1,OR(Dashboard!$C$13="All",A42=Dashboard!$C$13),OR(Dashboard!$C$14="All",B42=Dashboard!$C$14),OR(Dashboard!$C$15="All",C42=Dashboard!$C$15),OR(Dashboard!$C$16="All",K42=Dashboard!$C$16)),1,0) -> 1 | S42: =IF(M42=1,ROW()-1,"") -> 41 | T42: La Hacienda | V42: [Zebra Z-ULTIMATE 3000T] 3000T WHITE 82.55 x 37.3062 outside core Diameter 31.75, Labels per Roll 2000
A43: AlBurouj | B43: Local | C43: Automatic switch | D43: 1 | E43: 36 | F43: =IF(E43="","",D43*E43) -> 36 | G43: 46185 | H43: 9 | I43: =IF(OR(G43="",H43=""),"",G43+H43*7) -> 46248 | J43: Not Paid | K43: Pending | L43: =IF(A43="","",IF(OR(G43="",AND(G43>=Dashboard!$C$18,G43<=Dashboard!$C$19)),1,0)) -> 1 | M43: =IF(AND(L43=1,OR(Dashboard!$C$13="All",A43=Dashboard!$C$13),OR(Dashboard!$C$14="All",B43=Dashboard!$C$14),OR(Dashboard!$C$15="All",C43=Dashboard!$C$15),OR(Dashboard!$C$16="All",K43=Dashboard!$C$16),OR(Dashboard!$C$17="All",J43=Dashboard!$C$17)),1,0) -> 1 | N43: =IF(AND(L43=1,OR(Dashboard!$C$13="All",A43=Dashboard!$C$13),OR(Dashboard!$C$14="All",B43=Dashboard!$C$14),OR(Dashboard!$C$16="All",K43=Dashboard!$C$16),OR(Dashboard!$C$17="All",J43=Dashboard!$C$17)),1,0) -> 1 | O43: =IF(AND(L43=1,OR(Dashboard!$C$13="All",A43=Dashboard!$C$13),OR(Dashboard!$C$15="All",C43=Dashboard!$C$15),OR(Dashboard!$C$16="All",K43=Dashboard!$C$16),OR(Dashboard!$C$17="All",J43=Dashboard!$C$17)),1,0) -> 1 | P43: =IF(AND(L43=1,OR(Dashboard!$C$13="All",A43=Dashboard!$C$13),OR(Dashboard!$C$14="All",B43=Dashboard!$C$14),OR(Dashboard!$C$15="All",C43=Dashboard!$C$15),OR(Dashboard!$C$17="All",J43=Dashboard!$C$17)),1,0) -> 1 | Q43: =IF(AND(L43=1,OR(Dashboard!$C$14="All",B43=Dashboard!$C$14),OR(Dashboard!$C$15="All",C43=Dashboard!$C$15),OR(Dashboard!$C$16="All",K43=Dashboard!$C$16),OR(Dashboard!$C$17="All",J43=Dashboard!$C$17)),1,0) -> 1 | R43: =IF(AND(L43=1,OR(Dashboard!$C$13="All",A43=Dashboard!$C$13),OR(Dashboard!$C$14="All",B43=Dashboard!$C$14),OR(Dashboard!$C$15="All",C43=Dashboard!$C$15),OR(Dashboard!$C$16="All",K43=Dashboard!$C$16)),1,0) -> 1 | S43: =IF(M43=1,ROW()-1,"") -> 42 | T43: Marina | V43: A5 Paper Sticker Label - Blank
A44: Suez Canal Bank | B44: RICH RFID | C44: UHF On metal tags | D44: 3000 | E44: 95 | F44: =IF(E44="","",D44*E44) -> 285000 | G44: 46186 | H44: 9 | I44: =IF(OR(G44="",H44=""),"",G44+H44*7) -> 46249 | J44: Not Paid | K44: In Progress | L44: =IF(A44="","",IF(OR(G44="",AND(G44>=Dashboard!$C$18,G44<=Dashboard!$C$19)),1,0)) -> 1 | M44: =IF(AND(L44=1,OR(Dashboard!$C$13="All",A44=Dashboard!$C$13),OR(Dashboard!$C$14="All",B44=Dashboard!$C$14),OR(Dashboard!$C$15="All",C44=Dashboard!$C$15),OR(Dashboard!$C$16="All",K44=Dashboard!$C$16),OR(Dashboard!$C$17="All",J44=Dashboard!$C$17)),1,0) -> 1 | N44: =IF(AND(L44=1,OR(Dashboard!$C$13="All",A44=Dashboard!$C$13),OR(Dashboard!$C$14="All",B44=Dashboard!$C$14),OR(Dashboard!$C$16="All",K44=Dashboard!$C$16),OR(Dashboard!$C$17="All",J44=Dashboard!$C$17)),1,0) -> 1 | O44: =IF(AND(L44=1,OR(Dashboard!$C$13="All",A44=Dashboard!$C$13),OR(Dashboard!$C$15="All",C44=Dashboard!$C$15),OR(Dashboard!$C$16="All",K44=Dashboard!$C$16),OR(Dashboard!$C$17="All",J44=Dashboard!$C$17)),1,0) -> 1 | P44: =IF(AND(L44=1,OR(Dashboard!$C$13="All",A44=Dashboard!$C$13),OR(Dashboard!$C$14="All",B44=Dashboard!$C$14),OR(Dashboard!$C$15="All",C44=Dashboard!$C$15),OR(Dashboard!$C$17="All",J44=Dashboard!$C$17)),1,0) -> 1 | Q44: =IF(AND(L44=1,OR(Dashboard!$C$14="All",B44=Dashboard!$C$14),OR(Dashboard!$C$15="All",C44=Dashboard!$C$15),OR(Dashboard!$C$16="All",K44=Dashboard!$C$16),OR(Dashboard!$C$17="All",J44=Dashboard!$C$17)),1,0) -> 1 | R44: =IF(AND(L44=1,OR(Dashboard!$C$13="All",A44=Dashboard!$C$13),OR(Dashboard!$C$14="All",B44=Dashboard!$C$14),OR(Dashboard!$C$15="All",C44=Dashboard!$C$15),OR(Dashboard!$C$16="All",K44=Dashboard!$C$16)),1,0) -> 1 | S44: =IF(M44=1,ROW()-1,"") -> 43 | T44: Marbella | V44: Adapter 12V
A45: Akoya | B45: Metalcraft | C45: Dest windshield tags | D45: 300 | E45: 574 | F45: =IF(E45="","",D45*E45) -> 172200 | G45: 46187 | H45: 9 | I45: =IF(OR(G45="",H45=""),"",G45+H45*7) -> 46250 | J45: Not Paid | K45: Completed | L45: =IF(A45="","",IF(OR(G45="",AND(G45>=Dashboard!$C$18,G45<=Dashboard!$C$19)),1,0)) -> 1 | M45: =IF(AND(L45=1,OR(Dashboard!$C$13="All",A45=Dashboard!$C$13),OR(Dashboard!$C$14="All",B45=Dashboard!$C$14),OR(Dashboard!$C$15="All",C45=Dashboard!$C$15),OR(Dashboard!$C$16="All",K45=Dashboard!$C$16),OR(Dashboard!$C$17="All",J45=Dashboard!$C$17)),1,0) -> 1 | N45: =IF(AND(L45=1,OR(Dashboard!$C$13="All",A45=Dashboard!$C$13),OR(Dashboard!$C$14="All",B45=Dashboard!$C$14),OR(Dashboard!$C$16="All",K45=Dashboard!$C$16),OR(Dashboard!$C$17="All",J45=Dashboard!$C$17)),1,0) -> 1 | O45: =IF(AND(L45=1,OR(Dashboard!$C$13="All",A45=Dashboard!$C$13),OR(Dashboard!$C$15="All",C45=Dashboard!$C$15),OR(Dashboard!$C$16="All",K45=Dashboard!$C$16),OR(Dashboard!$C$17="All",J45=Dashboard!$C$17)),1,0) -> 1 | P45: =IF(AND(L45=1,OR(Dashboard!$C$13="All",A45=Dashboard!$C$13),OR(Dashboard!$C$14="All",B45=Dashboard!$C$14),OR(Dashboard!$C$15="All",C45=Dashboard!$C$15),OR(Dashboard!$C$17="All",J45=Dashboard!$C$17)),1,0) -> 1 | Q45: =IF(AND(L45=1,OR(Dashboard!$C$14="All",B45=Dashboard!$C$14),OR(Dashboard!$C$15="All",C45=Dashboard!$C$15),OR(Dashboard!$C$16="All",K45=Dashboard!$C$16),OR(Dashboard!$C$17="All",J45=Dashboard!$C$17)),1,0) -> 1 | R45: =IF(AND(L45=1,OR(Dashboard!$C$13="All",A45=Dashboard!$C$13),OR(Dashboard!$C$14="All",B45=Dashboard!$C$14),OR(Dashboard!$C$15="All",C45=Dashboard!$C$15),OR(Dashboard!$C$16="All",K45=Dashboard!$C$16)),1,0) -> 1 | S45: =IF(M45=1,ROW()-1,"") -> 44 | T45: El-Shorouk | V45: Adapter 24V
A46: Marshmallow | C46: Max50.10 | D46: 1 | E46: 558 | F46: =IF(E46="","",D46*E46) -> 558 | G46: 46188 | H46: 9 | I46: =IF(OR(G46="",H46=""),"",G46+H46*7) -> 46251 | J46: Not Paid | K46: Completed | L46: =IF(A46="","",IF(OR(G46="",AND(G46>=Dashboard!$C$18,G46<=Dashboard!$C$19)),1,0)) -> 1 | M46: =IF(AND(L46=1,OR(Dashboard!$C$13="All",A46=Dashboard!$C$13),OR(Dashboard!$C$14="All",B46=Dashboard!$C$14),OR(Dashboard!$C$15="All",C46=Dashboard!$C$15),OR(Dashboard!$C$16="All",K46=Dashboard!$C$16),OR(Dashboard!$C$17="All",J46=Dashboard!$C$17)),1,0) -> 1 | N46: =IF(AND(L46=1,OR(Dashboard!$C$13="All",A46=Dashboard!$C$13),OR(Dashboard!$C$14="All",B46=Dashboard!$C$14),OR(Dashboard!$C$16="All",K46=Dashboard!$C$16),OR(Dashboard!$C$17="All",J46=Dashboard!$C$17)),1,0) -> 1 | O46: =IF(AND(L46=1,OR(Dashboard!$C$13="All",A46=Dashboard!$C$13),OR(Dashboard!$C$15="All",C46=Dashboard!$C$15),OR(Dashboard!$C$16="All",K46=Dashboard!$C$16),OR(Dashboard!$C$17="All",J46=Dashboard!$C$17)),1,0) -> 1 | P46: =IF(AND(L46=1,OR(Dashboard!$C$13="All",A46=Dashboard!$C$13),OR(Dashboard!$C$14="All",B46=Dashboard!$C$14),OR(Dashboard!$C$15="All",C46=Dashboard!$C$15),OR(Dashboard!$C$17="All",J46=Dashboard!$C$17)),1,0) -> 1 | Q46: =IF(AND(L46=1,OR(Dashboard!$C$14="All",B46=Dashboard!$C$14),OR(Dashboard!$C$15="All",C46=Dashboard!$C$15),OR(Dashboard!$C$16="All",K46=Dashboard!$C$16),OR(Dashboard!$C$17="All",J46=Dashboard!$C$17)),1,0) -> 1 | R46: =IF(AND(L46=1,OR(Dashboard!$C$13="All",A46=Dashboard!$C$13),OR(Dashboard!$C$14="All",B46=Dashboard!$C$14),OR(Dashboard!$C$15="All",C46=Dashboard!$C$15),OR(Dashboard!$C$16="All",K46=Dashboard!$C$16)),1,0) -> 1 | S46: =IF(M46=1,ROW()-1,"") -> 45 | T46: Diamond Palace | V46: Adapter and charging cable
